Workbook

Sheet Mensal Fev 26
A1: Divergências com a base de dados SISBAR - Mensal Fevereiro 2026
A2: Nº Barra | B2: Nome | C2: Agente | D2: Área | E2: Questionamento SISBAR | F2: Parecer da Área
A3: 7647 | B3: R.ROCH-SP138 | C3: ELEKTRO | D3: =VLOOKUP(Tabela1[[#This Row],[Área]],'Corrige Area x UF'!$G$1:$I$168,2,FALSE) -> SP | E3: Baramentos presentes e ligados nos casos, porém com data futura no SISBAR (Após o fim do horizonte de estudo)
A4: 9385 | B4: ATLANT-PR138 | C4: COPEL D | D4: =VLOOKUP(Tabela1[[#This Row],[Área]],'Corrige Area x UF'!$G$1:$I$168,2,FALSE) -> PR | E4: Baramentos presentes e ligados nos casos, porém com data futura no SISBAR (Após o fim do horizonte de estudo)
A5: 9412 | B5: BANDE--PR138 | C5: COPEL D | D5: =VLOOKUP(Tabela1[[#This Row],[Área]],'Corrige Area x UF'!$G$1:$I$168,2,FALSE) -> PR | E5: Baramentos presentes e ligados nos casos, porém com data futura no SISBAR (Após o fim do horizonte de estudo)
A6: 9841 | B6: PINHA2-SC138 | C6: CELESC | D6: =VLOOKUP(Tabela1[[#This Row],[Área]],'Corrige Area x UF'!$G$1:$I$168,2,FALSE) -> SC | E6: Baramentos presentes e ligados nos casos, porém com data futura no SISBAR (Após o fim do horizonte de estudo)
A7: 10264 | B7: ELDO-B-RS023 | C7: CEEE D | D7: =VLOOKUP(Tabela1[[#This Row],[Área]],'Corrige Area x UF'!$G$1:$I$168,2,FALSE) -> RS | E7: Baramentos presentes e ligados nos casos, porém com data futura no SISBAR (Após o fim do horizonte de estudo)
A8: 10803 | B8: PN2-G3-SC138 | C8: CELESC | D8: =VLOOKUP(Tabela1[[#This Row],[Área]],'Corrige Area x UF'!$G$1:$I$168,2,FALSE) -> SC | E8: Baramentos presentes e ligados nos casos, porém com data futura no SISBAR (Após o fim do horizonte de estudo)
A9: 10931 | B9: DOM-F3-MS138 | C9: ENERGISA MS | D9: =VLOOKUP(Tabela1[[#This Row],[Área]],'Corrige Area x UF'!$G$1:$I$168,2,FALSE) -> MS | E9: Baramentos presentes e ligados nos casos, porém com data futura no SISBAR (Após o fim do horizonte de estudo)
A10: 44763 | B10: FEIJO1SIN001 | C10: OUTROS | D10: =VLOOKUP(Tabela1[[#This Row],[Área]],'Corrige Area x UF'!$G$1:$I$168,2,FALSE) -> AC | E10: Baramentos presentes e ligados nos casos, porém com data futura no SISBAR (Após o fim do horizonte de estudo)
A11: 44773 | B11: AVMT10-SP000 | C11: OUTROS | D11: =VLOOKUP(Tabela1[[#This Row],[Área]],'Corrige Area x UF'!$G$1:$I$168,2,FALSE) -> SP | E11: Baramentos presentes e ligados nos casos, porém com data futura no SISBAR (Após o fim do horizonte de estudo)
A12: 44774 | B12: AVMT10-SP013 | C12: OUTROS | D12: =VLOOKUP(Tabela1[[#This Row],[Área]],'Corrige Area x UF'!$G$1:$I$168,2,FALSE) -> SP | E12: Baramentos presentes e ligados nos casos, porém com data futura no SISBAR (Após o fim do horizonte de estudo)
A13: 45259 | B13: MATA.M-RR013 | C13: RORAIMA ENERGIA-N | D13: =VLOOKUP(Tabela1[[#This Row],[Área]],'Corrige Area x UF'!$G$1:$I$168,2,FALSE) -> RR | E13: Baramentos presentes e ligados nos casos, porém com data futura no SISBAR (Após o fim do horizonte de estudo)
A14: 45262 | B14: CANTA--RR013 | C14: RORAIMA ENERGIA-N | D14: =VLOOKUP(Tabela1[[#This Row],[Área]],'Corrige Area x UF'!$G$1:$I$168,2,FALSE) -> RR | E14: Baramentos presentes e ligados nos casos, porém com data futura no SISBAR (Após o fim do horizonte de estudo)
... A16: 45522 | B16: ICONRE-SP138 | C16: ENEL SP | D16: =VLOOKUP(Tabela1[[#This Row],[Área]],'Corrige Area x UF'!$G$1:$I$168,2,FALSE) -> SP | E16: Baramentos presentes e ligados nos casos, porém com data futura no SISBAR (Após o fim do horizonte de estudo)
A17: 47273 | B17: SOB-G3-MG138 | C17: CEMIG D | D17: =VLOOKUP(Tabela1[[#This Row],[Área]],'Corrige Area x UF'!$G$1:$I$168,2,FALSE) -> MG | E17: Baramentos presentes e ligados nos casos, porém com data futura no SISBAR (Após o fim do horizonte de estudo) | F17: Barra representada na BASE_DIST_MG_MANTIQUEIRA_E_PADRE_FIALHO_JAN25, deve ser mantida no caso do mensal de fevereiro/2026.
A18: 47274 | B18: RPA-G3-MG138 | C18: CEMIG D | D18: =VLOOKUP(Tabela1[[#This Row],[Área]],'Corrige Area x UF'!$G$1:$I$168,2,FALSE) -> MG | E18: Baramentos presentes e ligados nos casos, porém com data futura no SISBAR (Após o fim do horizonte de estudo) | F18: Barra representada na BASE_DIST_MG_TRIANGULO_JUN24, deve ser mantida no caso do mensal de fevereiro/2026.
A19: 47275 | B19: DIA-G3-MG138 | C19: CEMIG D | D19: =VLOOKUP(Tabela1[[#This Row],[Área]],'Corrige Area x UF'!$G$1:$I$168,2,FALSE) -> MG | E19: Baramentos presentes e ligados nos casos, porém com data futura no SISBAR (Após o fim do horizonte de estudo) | F19: Barra representada na BASE_DIST_MG_NORTE_JAN25, deve ser mantida no caso do mensal de fevereiro/2026.
A20: 47323 | B20: EMA-F3-PI069 | C20: EQUATORIAL PI | D20: =VLOOKUP(Tabela1[[#This Row],[Área]],'Corrige Area x UF'!$G$1:$I$168,2,FALSE) -> PI | E20: Baramentos presentes e ligados nos casos, porém com data futura no SISBAR (Após o fim do horizonte de estudo)
A21: 47342 | B21: IVA-G3-PR138 | C21: COPEL D | D21: =VLOOKUP(Tabela1[[#This Row],[Área]],'Corrige Area x UF'!$G$1:$I$168,2,FALSE) -> PR | E21: Baramentos presentes e ligados nos casos, porém com data futura no SISBAR (Após o fim do horizonte de estudo)
A22: 47584 | B22: COL-G3-PR138 | C22: COPEL D | D22: =VLOOKUP(Tabela1[[#This Row],[Área]],'Corrige Area x UF'!$G$1:$I$168,2,FALSE) -> PR | E22: Baramentos presentes e ligados nos casos, porém com data futura no SISBAR (Após o fim do horizonte de estudo)
A23: 48440 | B23: URUCU1-MG138 | C23: CEMIG D | D23: =VLOOKUP(Tabela1[[#This Row],[Área]],'Corrige Area x UF'!$G$1:$I$168,2,FALSE) -> MG | E23: Baramentos presentes e ligados nos casos, porém com data futura no SISBAR (Após o fim do horizonte de estudo)
A24: 3424 | B24: AGUAZU-SP088 | C24: EDP SP | D24: =VLOOKUP(Tabela1[[#This Row],[Área]],'Corrige Area x UF'!$G$1:$I$168,2,FALSE) -> SP | E24: Barramentos presentes nos casos (mas desligados), porém com data futura no sisbar (após o fim do horizonte do estudo)
A25: 7823 | B25: CAPEL3-MG500 | C25: OUTROS | D25: =VLOOKUP(Tabela1[[#This Row],[Área]],'Corrige Area x UF'!$G$1:$I$168,2,FALSE) -> MG | E25: Barramentos presentes nos casos (mas desligados), porém com data futura no sisbar (após o fim do horizonte do estudo)
A26: 7824 | B26: MCLAR6-MG013 | C26: OUTROS | D26: =VLOOKUP(Tabela1[[#This Row],[Área]],'Corrige Area x UF'!$G$1:$I$168,2,FALSE) -> MG | E26: Barramentos presentes nos casos (mas desligados), porém com data futura no sisbar (após o fim do horizonte do estudo)
A27: 7825 | B27: MCLAR6-MG000 | C27: OUTROS | D27: =VLOOKUP(Tabela1[[#This Row],[Área]],'Corrige Area x UF'!$G$1:$I$168,2,FALSE) -> MG | E27: Barramentos presentes nos casos (mas desligados), porém com data futura no sisbar (após o fim do horizonte do estudo)
A28: 7850 | B28: AR2AT5-SP000 | C28: OUTROS | D28: =VLOOKUP(Tabela1[[#This Row],[Área]],'Corrige Area x UF'!$G$1:$I$168,2,FALSE) -> SP | E28: Barramentos presentes nos casos (mas desligados), porém com data futura no sisbar (após o fim do horizonte do estudo)
A29: 7851 | B29: AR2AT5-SP013 | C29: OUTROS | D29: =VLOOKUP(Tabela1[[#This Row],[Área]],'Corrige Area x UF'!$G$1:$I$168,2,FALSE) -> SP | E29: Barramentos presentes nos casos (mas desligados), porém com data futura no sisbar (após o fim do horizonte do estudo)
A30: 10683 | B30: SPAL---PR138 | C30: COPEL D | D30: =VLOOKUP(Tabela1[[#This Row],[Área]],'Corrige Area x UF'!$G$1:$I$168,2,FALSE) -> PR | E30: Barramentos presentes nos casos (mas desligados), porém com data futura no sisbar (após o fim do horizonte do estudo)
A31: 10807 | B31: ENVASE-PR138 | C31: COPEL D | D31: =VLOOKUP(Tabela1[[#This Row],[Área]],'Corrige Area x UF'!$G$1:$I$168,2,FALSE) -> PR | E31: Barramentos presentes nos casos (mas desligados), porém com data futura no sisbar (após o fim do horizonte do estudo)
... A53: 1038 | B53: CAPIVA-RS138 | C53: CEEE D | D53: =VLOOKUP(Tabela1[[#This Row],[Área]],'Corrige Area x UF'!$G$1:$I$168,2,FALSE) -> RS | E53: Barramentos presentos nos casos, porém desativados no SISBAR
A54: 2178 | B54: ZILLO--SP138 | C54: CPFL PAULISTA | D54: =VLOOKUP(Tabela1[[#This Row],[Área]],'Corrige Area x UF'!$G$1:$I$168,2,FALSE) -> SP | E54: Barramentos presentos nos casos, porém desativados no SISBAR | F54: Essa barra representa um consumidor A2 que está com fornecimento suspenso. Foi desativada no SISBAR em 31/05/2025.
A55: 2662 | B55: BELGLA-ES138 | C55: EDP ES | D55: =VLOOKUP(Tabela1[[#This Row],[Área]],'Corrige Area x UF'!$G$1:$I$168,2,FALSE) -> ES | E55: Barramentos presentos nos casos, porém desativados no SISBAR | F55: Barra inclusa na rede de distribuição do ES dede 01/01/2025 (BASE_DIST_ES_JAN25), porém desativada (comentar para o caso do mensal)
A56: 5687 | B56: CPDNH2-MA069 | C56: EQUATORIAL MA-N | D56: =VLOOKUP(Tabela1[[#This Row],[Área]],'Corrige Area x UF'!$G$1:$I$168,2,FALSE) -> MA | E56: Barramentos presentos nos casos, porém desativados no SISBAR
A57: 5735 | B57: OLD----BA013 | C57: COELBA | D57: =VLOOKUP(Tabela1[[#This Row],[Área]],'Corrige Area x UF'!$G$1:$I$168,2,FALSE) -> BA/SE | E57: Barramentos presentos nos casos, porém desativados no SISBAR
A58: 6365 | B58: BARREI-BA138 | C58: COELBA | D58: =VLOOKUP(Tabela1[[#This Row],[Área]],'Corrige Area x UF'!$G$1:$I$168,2,FALSE) -> BA | E58: Barramentos presentos nos casos, porém desativados no SISBAR
A59: 7171 | B59: GEROUR-MG138 | C59: CEMIG D | D59: =VLOOKUP(Tabela1[[#This Row],[Área]],'Corrige Area x UF'!$G$1:$I$168,2,FALSE) -> MG | E59: Barramentos presentos nos casos, porém desativados no SISBAR | F59: Obra DIST_CEMIG-D_GERDAU O. B. E CONGONHAS que exclui a barra está prevista para 24/11/2026. Barra deve ser ligada nos casos do mensal de fevereiro/2026.
A60: 8026 | B60: CGD.BO-PB069 | C60: ENERGISA PB | D60: =VLOOKUP(Tabela1[[#This Row],[Área]],'Corrige Area x UF'!$G$1:$I$168,2,FALSE) -> PB/RN | E60: Barramentos presentos nos casos, porém desativados no SISBAR
A61: 8274 | B61: SANTAN-AP138 | C61: CEA | D61: =VLOOKUP(Tabela1[[#This Row],[Área]],'Corrige Area x UF'!$G$1:$I$168,2,FALSE) -> AP | E61: Barramentos presentos nos casos, porém desativados no SISBAR
A62: 8522 | B62: MANAU1-AM069 | C62: AMAZONAS ENERGIA | D62: =VLOOKUP(Tabela1[[#This Row],[Área]],'Corrige Area x UF'!$G$1:$I$168,2,FALSE) -> AM | E62: Barramentos presentos nos casos, porém desativados no SISBAR
...

Sheet Parecer
A1: Divergências com a base de dados SISBAR - Mensal Janeiro 2026 | F1: Parecer da Área | G1: Correção nos casos
A2: Nº Barra | B2: Nome | C2: Agente | D2: Área | E2: Questionamento SISBAR
A3: 2662 | B3: BELGLA-ES138 | C3: EDP ES | D3: ES | E3: Barramento presente nos casos, porém desativado no SISBAR | F3: Barra inclusa na rede de distribuição do ES dede 01/01/2025 (BASE_DIST_ES_JAN25), porém desativada (comentar para o caso do mensal) | G3: Pendente
A4: 45671 | B4: LUZIT3-GO000 | C4: OUTROS | D4: GO | E4: Barramento presente e ligado nos casos, porém com data futura no SISBAR (após o fim do horizonte de estudo) | G4: Sem Parecer
A5: 45672 | B5: LUZIT3-GO013 | C5: OUTROS | D5: GO | E5: Barramento presente e ligado nos casos, porém com data futura no SISBAR (após o fim do horizonte de estudo) | G5: Sem Parecer
A6: 48355 | B6: G.LESR-GO013 | C6: OUTROS | D6: GO | E6: Barramento presente e desligado nos casos, porém ativo no SISBAR (sem carga e geração) | G6: Sem Parecer
A7: 45673 | B7: XAVAT7-GO000 | C7: OUTROS | D7: GO | E7: Barramento ausente nos casos, porém ativo no SISBAR (sem carga e geração) | G7: Sem Parecer
A8: 45674 | B8: XAVAT7-GO013 | C8: OUTROS | D8: GO | E8: Barramento ausente nos casos, porém ativo no SISBAR (sem carga e geração) | G8: Sem Parecer
A9: 47413 | B9: CARAJA-GO000 | C9: OUTROS | D9: GO | E9: Barramento ausente nos casos, porém ativo no SISBAR (sem carga e geração) | G9: Sem Parecer
A10: 47414 | B10: CARAJA-GO013 | C10: OUTROS | D10: GO | E10: Barramento ausente nos casos, porém ativo no SISBAR (sem carga e geração) | G10: Sem Parecer
A11: 46401 | B11: PCHIQ2-MG138 | C11: CEMIG D | D11: MG | E11: Barramento presente nos casos, porém desativado no SISBAR | F11: Previsão da obra DIST_CEMIG-D_UFV PONTO CHIQUE 1 E 2 alterada para 01/09/2026. Na comparação com o SIGER deve ser excluída do mensal de fevereiro/2026. | G11: ok, deck AlteracoesComBaseSigerEm28-02-2026_DIST
A12: 46349 | B12: BURIT7-MG138 | C12: CEMIG D | D12: MG | E12: Barramento presente e ligado nos casos, porém com data futura no SISBAR (após o fim do horizonte de estudo) | F12: Previsão da obra DIST_CEMIG-D_BURITIZEIRO 7 E J.PINHEIRO 6 alterada para 24/03/2026. Na comparação com o SIGER deve ser excluída do mensal de fevereiro/2026. | G12: ok, deck AlteracoesComBaseSigerEm28-02-2026_DIST
A13: 46350 | B13: MCLAR8-MG138 | C13: CEMIG D | D13: MG | E13: Barramento presente e ligado nos casos, porém com data futura no SISBAR (após o fim do horizonte de estudo) | F13: Previsão da obra DIST_CEMIG-D_MONTES CLAROS 5, MONTES CLAROS 8, ETC alterada para 11/05/2026. Na comparação com o SIGER deve ser excluída do mensal de fevereiro/2026. | G13: ok, deck AlteracoesComBaseSigerEm28-02-2026_DIST
A14: 46406 | B14: JPINHEUFV034 | C14: CEMIG D | D14: MG | E14: Barramento presente e ligado nos casos, porém com data futura no SISBAR (após o fim do horizonte de estudo) | F14: Previsão da obra DIST_CEMIG-D_BURITIZEIRO 7 E J.PINHEIRO 6 alterada para 24/03/2026. Na comparação com o SIGER deve ser excluída do mensal de fevereiro/2026. | G14: ok, deck AlteracoesComBaseSigerEm28-02-2026_DIST
A15: 46408 | B15: P.CHIQ-MG034 | C15: CEMIG D | D15: MG | E15: Barramento presente e ligado nos casos, porém com data futura no SISBAR (após o fim do horizonte de estudo) | F15: Previsão da obra DIST_CEMIG-D_UFV PONTO CHIQUE 1 E 2 alterada para 01/09/2026. Na comparação com o SIGER deve ser excluída do mensal de fevereiro/2026. | G15: ok, deck AlteracoesComBaseSigerEm28-02-2026_DIST
A16: 47273 | B16: SOB-G3-MG138 | C16: CEMIG D | D16: MG | E16: Barramento presente e ligado nos casos, porém com data futura no SISBAR (após o fim do horizonte de estudo) | F16: Barra representada na BASE_DIST_MG_MANTIQUEIRA_E_PADRE_FIALHO_JAN25, deve ser mantida no caso do mensal de fevereiro/2026. | G16: ok, sem deck de ajuste
A17: 47274 | B17: RPA-G3-MG138 | C17: CEMIG D | D17: MG | E17: Barramento presente e ligado nos casos, porém com data futura no SISBAR (após o fim do horizonte de estudo) | F17: Barra representada na BASE_DIST_MG_TRIANGULO_JUN24, deve ser mantida no caso do mensal de fevereiro/2026. | G17: ok, sem deck de ajuste
A18: 47275 | B18: DIA-G3-MG138 | C18: CEMIG D | D18: MG | E18: Barramento presente e ligado nos casos, porém com data futura no SISBAR (após o fim do horizonte de estudo) | F18: Barra representada na BASE_DIST_MG_NORTE_JAN25, deve ser mantida no caso do mensal de fevereiro/2026. | G18: ok, sem deck de ajuste
A19: 7171 | B19: GEROUR-MG138 | C19: CEMIG D | D19: MG | E19: Barramento presente e desligado nos casos, porém ativo no SISBAR (sem carga e geração) | F19: Obra DIST_CEMIG-D_GERDAU O. B. E CONGONHAS que exclui a barra está prevista para 24/11/2026. Barra deve ser ligada nos casos do mensal de fevereiro/2026. | G19: ok, deck Ajustes_SISBAR
A20: 44776 | B20: VPALM5-MG138 | C20: CEMIG D | D20: MG | E20: Barramento presente e desligado nos casos, porém ativo no SISBAR (sem carga e geração) | F20: Obra DIST_CEMIG-D_VÁRZEA DA PALMA 5 concluída em 15/12/2025. Barra deve ser ligada nos casos do mensal de fevereiro/2026. | G20: ok, sem deck de ajuste (barra já está ligada)
A21: 45489 | B21: GSII1-UFV034 | C21: CEMIG D | D21: MG | E21: Barramento presente e desligado nos casos, porém ativo no SISBAR (sem carga e geração) | F21: Obra DIST_CEMIG-D_VÁRZEA DA PALMA 5 concluída em 15/12/2025. Barra deve ser ligada nos casos do mensal de fevereiro/2026. | G21: ok, sem deck de ajuste (barra já está ligada)
A22: 46400 | B22: PATRC3-MG138 | C22: CEMIG D | D22: MG | E22: Barramento ausente nos casos, porém ativo no SISBAR (com carga e/ou geração) | F22: Obra DIST_CEMIG-D-MG_SE PATROCÍNIO 3 prevista para 01/09/2026. Barra não deve ser incluída nos casos do mensal de fevereiro/2026. | G22: ok, sem deck de ajuste
... A43: 47282 | B43: AMP-G3-SP138 | C43: CPFL PAULISTA | D43: SP | E43: Barramento presente nos casos, porém desativado no SISBAR | F43: Esta barra foi criada indevidamente para a representação da geração da PCH Feixos [PCH.PH.SP.030260-0.01], quando da separação das usinas tipo II-B e tipo III dos barramentos de carga. Porém, essa usina está desativada já algum tempo e não era enviada previsão de geração. Desta forma, foi solicitada a desativação dela logo que foi criada. | G43: Pendente
A44: 47734 | B44: B.G-G3-GO138 | C44: CPFL PAULISTA | D44: SP | E44: Barramento presente nos casos, porém desativado no SISBAR | G44: Sem Parecer
A45: 17687 | B45: AM7-Y1-SP138 | C45: CPFL PAULISTA | D45: SP | E45: Barramento presente e desligado nos casos, porém ativo no SISBAR (sem carga e geração) | G45: Sem Parecer
A46: 13676 | B46: FRA5B1-SP138 | C46: CPFL PAULISTA | D46: SP | E46: Barramento ausente nos casos, porém ativo no SISBAR (sem carga e geração) | F46: Essa barra vai representar a futura SE Franca 5-Imperador, cuja obra está atrasada. Assim que concluída a obra, faremos a representação no caso Mensal. | G46: ok, sem deck de ajuste
A47: 23676 | B47: FRA5B2-SP138 | C47: CPFL PAULISTA | D47: SP | E47: Barramento ausente nos casos, porém ativo no SISBAR (sem carga e geração) | F47: Essa barra vai representar a futura SE Franca 5-Imperador, cuja obra está atrasada. Assim que concluída a obra, faremos a representação no caso Mensal. | G47: ok, sem deck de ajuste
A48: 7647 | B48: R.ROCH-SP138 | C48: ELEKTRO | D48: SP | E48: Barramento presente e ligado nos casos, porém com data futura no SISBAR (após o fim do horizonte de estudo) | G48: Sem Parecer
A49: 4146 | B49: SANSUN-SP138 | C49: ELEKTRO | D49: SP | E49: Barramento ausente nos casos, porém ativo no SISBAR (sem carga e geração) | G49: Sem Parecer
A50: 45519 | B50: REC-8--SP138 | C50: ENEL SP | D50: SP | E50: Barramento presente e ligado nos casos, porém com data futura no SISBAR (após o fim do horizonte de estudo) | G50: Sem Parecer
A51: 45522 | B51: ICONRE-SP138 | C51: ENEL SP | D51: SP | E51: Barramento presente e ligado nos casos, porém com data futura no SISBAR (após o fim do horizonte de estudo) | G51: Sem Parecer
A52: 44773 | B52: AVMT10-SP000 | C52: OUTROS | D52: SP | E52: Barramento presente e ligado nos casos, porém com data futura no SISBAR (após o fim do horizonte de estudo) | G52: Sem Parecer
A53: 44774 | B53: AVMT10-SP013 | C53: OUTROS | D53: SP | E53: Barramento presente e ligado nos casos, porém com data futura no SISBAR (após o fim do horizonte de estudo) | G53: Sem Parecer
A54: 41782 | B54: BANDT1-SP000 | C54: OUTROS | D54: SP | E54: Barramento presente e desligado nos casos, porém ativo no SISBAR (sem carga e geração) | G54: Sem Parecer
A55: 41783 | B55: BANDT1-SP034 | C55: OUTROS | D55: SP | E55: Barramento presente e desligado nos casos, porém ativo no SISBAR (sem carga e geração) | G55: Sem Parecer
A56: 41827 | B56: HBT231-SP088 | C56: OUTROS | D56: SP | E56: Barramento presente e desligado nos casos, porém ativo no SISBAR (sem carga e geração) | G56: Sem Parecer
A57: 41897 | B57: MNO-T4-SP000 | C57: OUTROS | D57: SP | E57: Barramento presente e desligado nos casos, porém ativo no SISBAR (sem carga e geração) | G57: Sem Parecer
A58: 44417 | B58: MNO-T4-SP013 | C58: OUTROS | D58: SP | E58: Barramento presente e desligado nos casos, porém ativo no SISBAR (sem carga e geração) | G58: Sem Parecer
A59: 7694 | B59: SCAETA-SP088 | C59: OUTROS | D59: SP | E59: Barramento ausente nos casos, porém ativo no SISBAR (sem carga e geração) | G59: Sem Parecer
... A70: 47387 | B70: SCL-Y2-SP230 | C70: SCALA DATA CENTERS | D70: SP | E70: Barramento ausente nos casos, porém ativo no SISBAR (sem carga e geração) | G70: Pendente

Sheet Corrige Area x UF
A1: SCS----SP088 | B1: =RIGHT(A1,5) -> SP088 | C1: =LEFT(B1,2) -> SP | D1: =LEFT(RIGHT(A1,5),2) -> SP | G1: Area | H1: UF | I1: Identification
G2: 1 | H2: RS | I2: RS - 525 kV
G3: 2 | H3: RS | I3: RS - 230 kV
G4: 3 | H4: RS | I4: RS - DIT/DIST
G5: 4 | H5: RS | I5: RS - DIT/DIST (Sul + Livramento 2)
G6: 5 | H6: RS | I6: RS - Consumidores RB
G7: 6 | H7: RS | I7: RS - Autoprodutores 230 kV
G8: 51 | H8: SC | I8: SC - 525 kV
G9: 52 | H9: SC | I9: SC - 230 kV
G10: 53 | H10: SC | I10: SC - DIT/DIST
G11: 54 | H11: SC | I11: SC - Consumidores RB
G12: 101 | H12: PR | I12: PR - 525 kV
G13: 102 | H13: PR | I13: PR - 230 kV
... G168: 903 | H168: RR | I168: RR - DIT/DIST
